<?xml version="1.0"?>
<robot name="box_bot" xmlns:xacro="http://www.ros.org/wiki/xacro">

  <material name="blue"><color rgba="0 0 1 1"/></material>
  <material name="black"><color rgba="0 0 0 1"/></material>

  <link name="base_link">
    <visual>
      <geometry><box size="0.6 0.4 0.2"/></geometry>
      <material name="blue"/>
    </visual>
    <collision>
      <geometry><box size="0.6 0.4 0.2"/></geometry>
    </collision>
    <inertial>
      <origin xyz="0.05 0 0" rpy="0 0 0"/>
      <mass value="5.0"/>
      <inertia ixx="0.1" ixy="0.0" ixz="0.0" iyy="0.1" iyz="0.0" izz="0.1"/>
    </inertial>  
  </link>

  <link name="left_wheel">
    <visual>
      <geometry><cylinder radius="0.1" length="0.05"/></geometry>
      <material name="black"/>
    </visual>
    <collision>
      <geometry><cylinder radius="0.1" length="0.05"/></geometry>
    </collision>
    <inertial>
      <mass value="0.5"/>
      <inertia ixx="0.01" ixy="0.0" ixz="0.0" iyy="0.01" iyz="0.0" izz="0.01"/>
    </inertial>
  </link>

  <link name="right_wheel">
    <visual>
      <geometry><cylinder radius="0.1" length="0.05"/></geometry>
      <material name="black"/>
    </visual>
    <collision>
      <geometry><cylinder radius="0.1" length="0.05"/></geometry>
    </collision>
    <inertial>
      <mass value="0.5"/>
      <inertia ixx="0.01" ixy="0.0" ixz="0.0" iyy="0.01" iyz="0.0" izz="0.01"/>
    </inertial>
  </link>

  <link name="caster_wheel">
    <visual>
      <geometry><sphere radius="0.05"/></geometry>
      <material name="black"/>
    </visual>
    <collision>
      <geometry><sphere radius="0.05"/></geometry>
    </collision>
    <inertial>
      <mass value="0.1"/>
      <inertia ixx="0.001" ixy="0.0" ixz="0.0" iyy="0.001" iyz="0.0" izz="0.001"/>
    </inertial>
  </link>

  <link name="laser_frame">
    <visual>
      <geometry><cylinder radius="0.05" length="0.04"/></geometry>
      <material name="black"/>
    </visual>
    <collision>
      <geometry><cylinder radius="0.05" length="0.04"/></geometry>
    </collision>
    <inertial>
      <mass value="0.1"/>
      <inertia ixx="0.001" ixy="0.0" ixz="0.0" iyy="0.001" iyz="0.0" izz="0.001"/>
    </inertial>
  </link>

  <joint name="left_wheel_joint" type="continuous">
    <parent link="base_link"/>
    <child link="left_wheel"/>
    <origin xyz="-0.1 0.22 -0.1" rpy="-1.57 0 0"/> <axis xyz="0 0 1"/>
  </joint>

  <joint name="right_wheel_joint" type="continuous">
    <parent link="base_link"/>
    <child link="right_wheel"/>
    <origin xyz="-0.1 -0.22 -0.1" rpy="-1.57 0 0"/>
    <axis xyz="0 0 1"/>
  </joint>

  <joint name="caster_wheel_joint" type="fixed">
    <parent link="base_link"/>
    <child link="caster_wheel"/>
    <origin xyz="0.2 0 -0.15" rpy="0 0 0"/> </joint>

  <joint name="laser_joint" type="fixed">
    <parent link="base_link"/>
    <child link="laser_frame"/>
    <origin xyz="0.1 0 0.12" rpy="0 0 0"/>
  </joint>

  <gazebo reference="caster_wheel">
    <mu1 value="0.001"/>
    <mu2 value="0.001"/>
  </gazebo>

  <gazebo>
    <plugin name="diff_drive" filename="libgazebo_ros_diff_drive.so">
      <left_joint>left_wheel_joint</left_joint>
      <right_joint>right_wheel_joint</right_joint>
      <wheel_separation>0.44</wheel_separation>
      <wheel_diameter>0.2</wheel_diameter>
      <publish_wheel_tf>true</publish_wheel_tf>
    <publish_wheel_joint_state>true</publish_wheel_joint_state>
      <max_wheel_torque>10</max_wheel_torque>
      <max_wheel_acceleration>1.0</max_wheel_acceleration>
      
      <publish_odom>true</publish_odom>
      <publish_odom_tf>true</publish_odom_tf>
      <robot_base_frame>base_link</robot_base_frame>
    </plugin>
  </gazebo>

  <gazebo reference="laser_frame">
    <sensor name="lidar" type="ray">
      <visualize>true</visualize>
      <ray>
        <scan>
          <horizontal><samples>360</samples><min_angle>-3.14</min_angle><max_angle>3.14</max_angle></horizontal>
        </scan>
        <range><min>0.1</min><max>12.0</max></range>
      </ray>
      <plugin name="lidar_controller" filename="libgazebo_ros_ray_sensor.so">
        <ros><remapping>~/out:=scan</remapping></ros>
        <output_type>sensor_msgs/LaserScan</output_type>
        <frame_name>laser_frame</frame_name>
      </plugin>
    </sensor>
  </gazebo>

</robot>
